<?xml version="1.0"?>
<robot name="fml_car" xmlns:xacro="http://ros.org/wiki/xacro">

  <!-- Define robot constants -->
  <xacro:property name="base_width" value="0.329"/>
  <xacro:property name="base_length" value="0.686"/>
  <xacro:property name="base_height" value="0.128"/>

  <xacro:property name="wheel_radius" value="0.114"/>
  <xacro:property name="wheel_width" value="0.045"/>
  <xacro:property name="wheel_ygap" value="0.025"/>
  <xacro:property name="wheel_zoff" value="0.05"/>
  <xacro:property name="wheel_xoff" value="0.202"/>

  <xacro:property name="caster_xoff" value="0.202"/>

    <!-- Robot Base -->
    <link name="base_link">
    <visual>
      <geometry>
        <box size="${base_length} ${base_width} ${base_height}"/>
      </geometry>
      <material name="Cyan">
        <color rgba="0 1.0 1.0 1.0"/>
      </material>
    </visual>
  </link>

  <!-- Robot Footprint -->
  <link name="base_footprint"/>
  <joint name="base_joint" type="fixed">
    <parent link="base_link"/>
    <child link="base_footprint"/>
    <origin xyz="0.0 0.0 ${-(wheel_radius+wheel_zoff)}" rpy="0 0 0"/>
  </joint>

      <!-- Wheels -->
  <xacro:macro name="wheel" params="prefix x_reflect y_reflect">
    <link name="${prefix}_link">
      <visual>
        <origin xyz="0 0 0" rpy="${pi/2} 0 0"/>
        <geometry>
            <cylinder radius="${wheel_radius}" length="${wheel_width}"/>
        </geometry>
        <material name="Gray">
          <color rgba="0.5 0.5 0.5 1.0"/>
        </material>
      </visual>
    </link>

    <joint name="${prefix}_joint" type="continuous">
      <parent link="base_link"/>
      <child link="${prefix}_link"/>
      <origin xyz="${x_reflect*wheel_xoff} ${y_reflect*(base_width/2+wheel_ygap)} ${-wheel_zoff}" rpy="0 0 0"/>
      <axis xyz="0 1 0"/>
    </joint>
  </xacro:macro>

  <xacro:wheel prefix="drivewhl_l" x_reflect="-1" y_reflect="1" />
  <xacro:wheel prefix="drivewhl_r" x_reflect="-1" y_reflect="-1" />

  <!-- Caster Wheel -->
  <link name="front_caster">
    <visual>
      <geometry>
        <sphere radius="${(wheel_radius+wheel_zoff-(base_height/2))}"/>
      </geometry>
      <material name="Cyan">
        <color rgba="0 1.0 1.0 1.0"/>
      </material>
    </visual>
  </link>

  <joint name="caster_joint" type="fixed">
    <parent link="base_link"/>
    <child link="front_caster"/>
    <origin xyz="${caster_xoff} 0.0 ${-(base_height/2)}" rpy="0 0 0"/>
  </joint>

    <joint name="laser_joint" type="fixed">
            <parent link="base_link"/>
            <child link="laser_frame"/>
            <origin xyz="0.1 0 0.175" rpy="0 0 0"/>
    </joint>

    <link name="laser_frame">
        <link name="laser_frame">
            <visual>
                <geometry>
                    <cylinder radius="0.05" length="0.04"/>
                </geometry>
                <material name="red"/>
            </visual>
            <collision>
                <geometry>
                    <cylinder radius="0.05" length="0.04"/>
                </geometry>
            </collision>
        </link>
    </link>

    <joint name="imu_joint" type="fixed">
        <parent link="base_link"/>
        <child link="imu_frame"/>
        <origin xyz="0.05 0 0.175" rpy="0 0 0"/>
    </joint>

    <link name="imu_frame">
        <link name="imu_frame">
            <visual>
                <geometry>
                    <box size="0.01 0.01 0.01"/>
                </geometry>
                <material name="red"/>
            </visual>
            <collision>
                <geometry>
                    <box size="0.01 0.01 0.01"/>
                </geometry>
            </collision>
        </link>
    </link>


</robot>
